Workbook

Sheet Farmin_perustiedot
A1: Refitted Farm
A3: Building Inner Dimensions | D3: Rakennuksen ulkodimensiot (esim.)
A4: Length | B4: 30 | C4: m | D4: Length | E4: =B4+2*0.3 -> 30.6 | F4: m | I4: €
A5: Width | B5: 20 | C5: m | D5: Width | E5: =B5+2*0.3 -> 20.6 | F5: m | I5: €
A6: Height | B6: 2.6 | C6: m | D6: Height | E6: =B6+0.4+0.3 -> 3.3 | F6: m
A8: Floor Area | B8: =B4*B5 -> 600 | C8: m² | D8: Farming Automation Provider | G8: High Automation
A9: Buildin Envelope Area | B9: =E4*E5+2*E4*3+2*(E5-2*0.3)*3 -> 933.96 | C9: m²
A11: Floor Usage Efficiench | B11: 0.75
A12: Cultivation Area per Floor | B12: =B15/B13 -> 450 | C12: m2
A13: Number of Floors | B13: 6
A15: Total | B15: =B8*B11*B13 -> 2700 | C15: m2
D18: Energy Consumption | G18: Potential to use excess heat to warm nearby buildings:
D19: LED Light Energy Consumption | E19: 80 | F19: W | G19: Energy production per year | H19: =E24*0.7*B15 -> 1341068.4 | I19: kWh
D20: Lights On per Year | E20: =18*365 -> 6570 | F20: h
D21: Climate Control Energy Consumption per m2 | E21: =E19*0.25 -> 20 | F21: W | G21: Winter energy production | H21: =0.4*H19 -> 536427.36 | I21: kWh
D22: Other per m2 | E22: =E19*0.1 -> 8 | F22: W
G23: Value of heat energy | H23: 0.04 | I23: €/kWh
D24: Total per m2 | E24: =(E21+E19+E22)/1000*E20 -> 709.56 | F24: kWh
G25: Total | H25: =H23*H21 -> 21457.094 | I25: €
A26: Income: | D26: Energy Price | E26: 0.08 | F26: €/kWh
A27: Product 1 (Lettuce) | B27: 0.8 | D27: Energy Cost | E27: =E26*E24*B15 -> 153264.96 | F27: €/vuosi
A28: Yield per year per m2 | B28: 70 | C28: kg
A29: Cultivation Area | B29: =B15*B27 -> 2160 | C29: m² | D29: Energy Consumption per kg of product | E29: =E24/70 -> 10.136571 | F29: kWh/kg of Lettuce
A30: Yarly Yield | B30: =B28*B29 -> 151200 | C30: kg
A31: Price per Kg | B31: 7 | C31: € | D31: Energy Cost per kg of lettuce | E31: =E29*E26 -> 0.81092571 | F31: €/kg
A32: Total | B32: =B28*B29*B31 -> 1058400 | C32: €
A34: Product 2 (Basil) | B34: 0.2
A35: Yield per year per m2 | B35: 30 | C35: kg
A36: Cultivation Area | B36: =B34*B15 -> 540 | C36: m2
A37: Yarly Yield | B37: =B36*B35 -> 16200 | C37: kg
A38: Price per Kg | B38: 20 | C38: € | D38: Required Power | E38: =100*B15/1000 -> 270 | F38: kWp
A39: Total | B39: =B35*B36*B38 -> 324000 | C39: €
D44: Other Costs per Cultivation m2 | F44: 75
A47: Total Yearly Sales | B47: =B32+B39 -> 1382400 | C47: €
A49: Costs
A50: Electricity | B50: =E27 -> 153264.96 | C50: €
A51: Labor | B51: =2100*2*12*1.3 -> 65520 | C51: €
A52: Other | B52: =F44*B15 -> 202500 | C52: €
A53: Logistics | B53: =0.35*(B30+B37) -> 58590 | C53: €
A54: Building Maintenance | B54: =15*B9 -> 14009.4 | C54: €
...

Sheet Investointi
A1: Refitted Farm
A5: Investment Costs
A7: Building | B7: =500*Farmin_perustiedot!B9 -> 466980 | C7: €
A8: Farmin Equipment | B8: =950*Farmin_perustiedot!B15 -> 2565000 | C8: €
A9: Other | B9: 50000 | C9: €
A11: Subsidies | B11: =0.3*B8+0.3*B7 -> 909594 | C11: €
A13: Total | B13: =B7+B8+B9-B11 -> 2172386 | C13: €
A16: Key Business Numbers:
A18: Yearly Sales | B18: =Farmin_perustiedot!B47 -> 1382400 | C18: €
A19: Yearly Costs | B19: =Farmin_perustiedot!B55 -> 493884.36 | C19: €
A21: Yearly Margin | B21: =B18-B19 -> 888515.64 | C21: €

Sheet Takaisinmaksu
A1: MTK-Farmi
A3: Presumptions
A5: Investment Costs | C5: =Investointi!B13 -> 2172386 | D5: €
A6: Yearly Sales Margin | C6: =Investointi!B21 -> 888515.64 | D6: €
A8: Discount Factor | C8: 0.05 | D8: *100 % per Year
A9: Year 1 operational efficiency ( Accounting for the fact that it takes time to get the operation to run at full speed) | J9: 0.8
A10: Yearly increase in efficiency | C10: 0.015 | D10: *100 % per vuosi
A15: Year | B15: Discounted Sales | D15: Cumulative Discounted Sales | F15: Replace Invest. | G15: Net
A16: 0 | B16: =$C$6/(1+$C$8)^A16*J9+Farmin_perustiedot!H25 -> 732269.61 | D16: =B16 -> 732269.61 | G16: =-$C$5+D16 -> -1440116.4
A17: 1 | B17: =$C$6*(1+$C$10)^A17/(1+$C$8)^A17 -> 858898.45 | D17: =B17+D16 -> 1591168.1 | G17: =G16+B17-F17 -> -581217.94
A18: 2 | B18: =$C$6*(1+$C$10)^A18/(1+$C$8)^A18 -> 830268.5 | D18: =B18+D17 -> 2421436.6 | G18: =G17+B18-F18 -> 249050.56
A19: 3 | B19: =$C$6*(1+$C$10)^A19/(1+$C$8)^A19 -> 802592.89 | D19: =B19+D18 -> 3224029.4 | G19: =G18+B19-F19 -> 1051643.4
A20: 4 | B20: =$C$6*(1+$C$10)^A20/(1+$C$8)^A20 -> 775839.79 | D20: =B20+D19 -> 3999869.2 | F20: 50000 | G20: =G19+B20-F20 -> 1777483.2
A21: 5 | B21: =$C$6*(1+$C$10)^A21/(1+$C$8)^A21 -> 749978.46 | D21: =B21+D20 -> 4749847.7 | F21: 50000 | G21: =G20+B21-F21 -> 2477461.7
A22: 6 | B22: =$C$6*(1+$C$10)^A22/(1+$C$8)^A22 -> 724979.18 | D22: =B22+D21 -> 5474826.9 | F22: 50000 | G22: =G21+B22-F22 -> 3152440.9
A23: 7 | B23: =$C$6*(1+$C$10)^A23/(1+$C$8)^A23 -> 700813.21 | D23: =B23+D22 -> 6175640.1 | F23: 100000 | G23: =G22+B23-F23 -> 3753254.1
A24: 8 | B24: =$C$6*(1+$C$10)^A24/(1+$C$8)^A24 -> 677452.77 | D24: =B24+D23 -> 6853092.9 | F24: 25000 | G24: =G23+B24-F24 -> 4405706.9
A25: 9 | B25: =$C$6*(1+$C$10)^A25/(1+$C$8)^A25 -> 654871.01 | D25: =B25+D24 -> 7507963.9 | F25: 25000 | G25: =G24+B25-F25 -> 5035577.9
A26: 10 | B26: =$C$6*(1+$C$10)^A26/(1+$C$8)^A26 -> 633041.98 | D26: =B26+D25 -> 8141005.9 | G26: =G25+B26-F26 -> 5668619.9
